Workbook

Sheet ReadMeFirst
A1: Read Me First - Documentation for this Excel Workbook
B3: Date | C3: 44718 | D3: 6C
B4: Description | C4: This Excel Workbook holds TrackR Production data on Components, Employees, WholeSale Prices
C5: This Excel Workbook documents the many AS-Is calculations of the Trackr manufacturing process.
C6: This Excel Workbook also holds the additional To-Be Calculation sheets for Team Member - <your name here>
C7: The TrackR Production Data Sheets (B, F, H, J, L) and As-Is Sheets (C, D, E, G, K) were developed thru Team Work
C8: The As-Is sheets (C, D, E, G, K) were duplicated, then modified, to make To-Be Sheets (<sheet codes here>)for one person's work
C9: The As-Is sheets (C, D, E, G, K) were not adjusted in any way during the To-Be phase of this work.
C10: These sheets hold calculation models of the TrackR Production business, and can be used to generate predictions
C11: Many cells in these sheets use values that come from other sheets, thru Vlookup, =<Cell>, or similar functions.
C12: All Core Data Values (walking speed, assembly times, costs, etc.) have Minimum and Maximum values, not just one value
B14: Authors Team
B15: To-Be Sheets Author
B17: Short Forms
A18: 1 | B18: Prodn | C18: Production
A19: 2 | B19: Avg | C19: Average
A20: 3 | B20: Ver | C20: Version
A21: 4 | B21: A Prefix in Tab Names | C21: As-Is
A22: 5 | B22: T Prefix in Tab Names | C22: To-Be
A23: 6 | B23: P&L | C23: Profit and Loss
B25: Below is the list of all the sheets included along with their authors
A27: Code | B27: Tab Name | C27: Full Sheet Name | D27: Authors | E27: Notes
A28: A | B28: ReadMeFirst
A29: B | B29: Components | C29: Components, Pricing, Inventory Location
A30: C | B30: A Picking | C30: Picking Distances, Times, Walking Speeds
A31: D | B31: A Assembly | C31: TrackR Assembly, Responses to Failures, Times, Costs, Summaries | E31: See the videos
A32: E | B32: A P&L | C32: As-Is Profit and Loss
A33: F | B33: Employees | C33: Employees, PayRates, Attitudes
A34: G | B34: A Schedule | C34: As-Is 8 hour Three Table Schedule for 9 Assembly Workers | E34: 10 minutes break every hour, 30 minute lunch
A35: H | B35: WholeSale | C35: TrackR WholeSale Prices for 2016 to 2019
A36: J | B36: DayProdn | C36: Day's Production of TrackR Versions - Data Table
A37: K | B37: VerAvgProdn | C37: Average Daily Production of TrackR versions 2018 Q4 and 2019 Q1 | E37: Pivot Table
A38: L | B38: POs | C38: Purchase Order Data for Components
B40: Assumptions: | C40: (some Assumptions are given at the top of sheets - ie Picking)
A41: 1 | B41: The time period of this project work
B42: Choice 1 | C42: as of now 2021
B43: Choice 2 | C43: as of May 2019
B44: Decision | C44: Choice 2

Sheet Components
A1: All Components, No TrackR Version Totals | K1: All Components, with TrackR Version Totals
H2: Unit Cost | K2: TrackR A | O2: Unit Cost
A3: ID # | B3: Manufacturer | C3: Part Number | D3: Description | E3: TrackR Version | F3: Shelf | G3: Bay | H3: Min | I3: Max | K3: ID # | L3: Part Number | M3: Description | N3: TrackR Version | O3: Min | P3: Max
A4: 1 | B4: Mitchell’s Plastics | C4: MPC432119-2 | D4: Vulcanized Rubber casing | E4: ABC | F4: =VLOOKUP(Table1[[#This Row],[Part Number]],'Shelving Inventory list'!$A$2:$C$72,2,FALSE) -> 10 | G4: =VLOOKUP(Table1[[#This Row],[Part Number]],'Shelving Inventory list'!$A$2:$C$72,3,FALSE) -> C | H4: =MIN(VLOOKUP(C4,POs!$B$2:$E$46,4,FALSE)) -> 6.606 | I4: =(Table1[[#This Row],[Min]]+0.05*Table1[[#This Row],[Min]]) -> 6.9363 | K4: 1 | L4: Mitchell’s Plastics | M4: MPC432119-2 | N4: ABC | O4: =MIN(VLOOKUP(M4,POs!$B$2:$E$46,4,FALSE)) -> 6.606 | P4: =(Table3[[#This Row],[Min]]+0.05*Table3[[#This Row],[Min]]) -> 6.9363
A5: 2 | B5: Mitchell’s Plastics | C5: MPC44422 | D5: Rigid plastic pins | E5: ABC | F5: =VLOOKUP(Table1[[#This Row],[Part Number]],'Shelving Inventory list'!$A$2:$C$72,2,FALSE) -> 10 | G5: =VLOOKUP(Table1[[#This Row],[Part Number]],'Shelving Inventory list'!$A$2:$C$72,3,FALSE) -> E | H5: =MIN(VLOOKUP(C5,POs!$B$2:$E$46,4,FALSE)) -> 0.081 | I5: =(Table1[[#This Row],[Min]]+0.05*Table1[[#This Row],[Min]]) -> 0.08505 | K5: 2 | L5: Mitchell’s Plastics | M5: MPC44422 | N5: ABC | O5: =MIN(VLOOKUP(M5,POs!$B$2:$E$46,4,FALSE)) -> 0.081 | P5: =(Table3[[#This Row],[Min]]+0.05*Table3[[#This Row],[Min]]) -> 0.08505
A6: 3 | B6: American Vanadium | C6: SFLV25 | D6: Slimflex Lithium-Vanadium printed battery | E6: ABC | F6: =VLOOKUP(Table1[[#This Row],[Part Number]],'Shelving Inventory list'!$A$2:$C$72,2,FALSE) -> 2 | G6: =VLOOKUP(Table1[[#This Row],[Part Number]],'Shelving Inventory list'!$A$2:$C$72,3,FALSE) -> A | H6: =MIN(VLOOKUP(C6,POs!$B$2:$E$46,4,FALSE)) -> 17.42 | I6: =(Table1[[#This Row],[Min]]+0.05*Table1[[#This Row],[Min]]) -> 18.291 | K6: 3 | L6: American Vanadium | M6: SFLV25 | N6: ABC | O6: =MIN(VLOOKUP(M6,POs!$B$2:$E$46,4,FALSE)) -> 17.42 | P6: =(Table3[[#This Row],[Min]]+0.05*Table3[[#This Row],[Min]]) -> 18.291
A7: 4 | B7: Foxconn | C7: FnOFI-GN1212 | D7: Main printed circuit board (PCB) | E7: ABC | F7: =VLOOKUP(Table1[[#This Row],[Part Number]],'Shelving Inventory list'!$A$2:$C$72,2,FALSE) -> 4 | G7: =VLOOKUP(Table1[[#This Row],[Part Number]],'Shelving Inventory list'!$A$2:$C$72,3,FALSE) -> D | H7: =MIN(VLOOKUP(C7,POs!$B$2:$E$46,4,FALSE)) -> 14.99 | I7: =(Table1[[#This Row],[Min]]+0.05*Table1[[#This Row],[Min]]) -> 15.7395 | K7: 4 | L7: Foxconn | M7: FnOFI-GN1212 | N7: ABC | O7: =MIN(VLOOKUP(M7,POs!$B$2:$E$46,4,FALSE)) -> 14.99 | P7: =(Table3[[#This Row],[Min]]+0.05*Table3[[#This Row],[Min]]) -> 15.7395
A8: 5 | B8: Qualcomm | C8: BD2098733AAB | D8: Secure housing for orientation equipment | E8: ABC | F8: =VLOOKUP(Table1[[#This Row],[Part Number]],'Shelving Inventory list'!$A$2:$C$72,2,FALSE) -> 5 | G8: =VLOOKUP(Table1[[#This Row],[Part Number]],'Shelving Inventory list'!$A$2:$C$72,3,FALSE) -> E | H8: =MIN(VLOOKUP(C8,POs!$B$2:$E$46,4,FALSE)) -> 4.15 | I8: =(Table1[[#This Row],[Min]]+0.05*Table1[[#This Row],[Min]]) -> 4.3575 | K8: 5 | L8: Qualcomm | M8: BD2098733AAB | N8: ABC | O8: =MIN(VLOOKUP(M8,POs!$B$2:$E$46,4,FALSE)) -> 4.15 | P8: =(Table3[[#This Row],[Min]]+0.05*Table3[[#This Row],[Min]]) -> 4.3575
A9: 6 | B9: Qualcomm | C9: BD20911131BB | D9: Micro-transmitter for LTE communication | E9: ABC | F9: =VLOOKUP(Table1[[#This Row],[Part Number]],'Shelving Inventory list'!$A$2:$C$72,2,FALSE) -> 6 | G9: =VLOOKUP(Table1[[#This Row],[Part Number]],'Shelving Inventory list'!$A$2:$C$72,3,FALSE) -> B | H9: =MIN(VLOOKUP(C9,POs!$B$2:$E$46,4,FALSE)) -> 1.88 | I9: =(Table1[[#This Row],[Min]]+0.05*Table1[[#This Row],[Min]]) -> 1.974 | K9: 6 | L9: Qualcomm | M9: BD20911131BB | N9: ABC | O9: =MIN(VLOOKUP(M9,POs!$B$2:$E$46,4,FALSE)) -> 1.88 | P9: =(Table3[[#This Row],[Min]]+0.05*Table3[[#This Row],[Min]]) -> 1.974
A10: 7 | B10: ST Microelectronics | C10: HG213123-221 | D10: 3-axis digital gyroscope | E10: ABC | F10: =VLOOKUP(Table1[[#This Row],[Part Number]],'Shelving Inventory list'!$A$2:$C$72,2,FALSE) -> 7 | G10: =VLOOKUP(Table1[[#This Row],[Part Number]],'Shelving Inventory list'!$A$2:$C$72,3,FALSE) -> B | H10: =MIN(VLOOKUP(C10,POs!$B$2:$E$46,4,FALSE)) -> 0.57 | I10: =(Table1[[#This Row],[Min]]+0.05*Table1[[#This Row],[Min]]) -> 0.5985 | K10: 7 | L10: ST Microelectronics | M10: HG213123-221 | N10: ABC | O10: =MIN(VLOOKUP(M10,POs!$B$2:$E$46,4,FALSE)) -> 0.57 | P10: =(Table3[[#This Row],[Min]]+0.05*Table3[[#This Row],[Min]]) -> 0.5985
A11: 8 | B11: ST Microelectronics | C11: STMA11233 | D11: 2-axis analogue accelerometer | E11: ABC | F11: =VLOOKUP(Table1[[#This Row],[Part Number]],'Shelving Inventory list'!$A$2:$C$72,2,FALSE) -> 8 | G11: =VLOOKUP(Table1[[#This Row],[Part Number]],'Shelving Inventory list'!$A$2:$C$72,3,FALSE) -> E | H11: =MIN(VLOOKUP(C11,POs!$B$2:$E$46,4,FALSE)) -> 0.31 | I11: =(Table1[[#This Row],[Min]]+0.05*Table1[[#This Row],[Min]]) -> 0.3255 | K11: 8 | L11: ST Microelectronics | M11: STMA11233 | N11: ABC | O11: =MIN(VLOOKUP(M11,POs!$B$2:$E$46,4,FALSE)) -> 0.31 | P11: =(Table3[[#This Row],[Min]]+0.05*Table3[[#This Row],[Min]]) -> 0.3255
A12: 9 | B12: Samsung | C12: SS98AAIS | D12: 18mm x 29mm OLED screen | E12: ABC | F12: =VLOOKUP(Table1[[#This Row],[Part Number]],'Shelving Inventory list'!$A$2:$C$72,2,FALSE) -> 7 | G12: =VLOOKUP(Table1[[#This Row],[Part Number]],'Shelving Inventory list'!$A$2:$C$72,3,FALSE) -> E | H12: =MIN(VLOOKUP(C12,POs!$B$2:$E$46,4,FALSE)) -> 38.15 | I12: =(Table1[[#This Row],[Min]]+0.05*Table1[[#This Row],[Min]]) -> 40.0575 | K12: 9 | L12: Samsung | M12: SS98AAIS | N12: ABC | O12: =MIN(VLOOKUP(M12,POs!$B$2:$E$46,4,FALSE)) -> 38.15 | P12: =(Table3[[#This Row],[Min]]+0.05*Table3[[#This Row],[Min]]) -> 40.0575
A13: 10 | B13: Sandisk | C13: SDMALBB3033G | D13: 2GB FLASH NAND | E13: ABC | F13: =VLOOKUP(Table1[[#This Row],[Part Number]],'Shelving Inventory list'!$A$2:$C$72,2,FALSE) -> 3 | G13: =VLOOKUP(Table1[[#This Row],[Part Number]],'Shelving Inventory list'!$A$2:$C$72,3,FALSE) -> C | H13: =MIN(VLOOKUP(C13,POs!$B$2:$E$46,4,FALSE)) -> 4 | I13: =(Table1[[#This Row],[Min]]+0.05*Table1[[#This Row],[Min]]) -> 4.2 | K13: 10 | L13: Sandisk | M13: SDMALBB3033G | N13: ABC | O13: =MIN(VLOOKUP(M13,POs!$B$2:$E$46,4,FALSE)) -> 4 | P13: =(Table3[[#This Row],[Min]]+0.05*Table3[[#This Row],[Min]]) -> 4.2
A14: 11 | B14: BlueGiga | C14: BLE112 | D14: Bluetooth 4.0 low energy chipset | E14: ABC | F14: =VLOOKUP(Table1[[#This Row],[Part Number]],'Shelving Inventory list'!$A$2:$C$72,2,FALSE) -> 1 | G14: =VLOOKUP(Table1[[#This Row],[Part Number]],'Shelving Inventory list'!$A$2:$C$72,3,FALSE) -> A | H14: =MIN(VLOOKUP(C14,POs!$B$2:$E$46,4,FALSE)) -> 2 | I14: =(Table1[[#This Row],[Min]]+0.05*Table1[[#This Row],[Min]]) -> 2.1 | K14: 11 | L14: BlueGiga | M14: BLE112 | N14: ABC | O14: =MIN(VLOOKUP(M14,POs!$B$2:$E$46,4,FALSE)) -> 2 | P14: =(Table3[[#This Row],[Min]]+0.05*Table3[[#This Row],[Min]]) -> 2.1
A15: 12 | B15: Banda Bracelets (HK) Ltd. | C15: LS1121 | D15: Plastic wrist strap | E15: B | F15: =VLOOKUP(Table1[[#This Row],[Part Number]],'Shelving Inventory list'!$A$2:$C$72,2,FALSE) -> 14 | G15: =VLOOKUP(Table1[[#This Row],[Part Number]],'Shelving Inventory list'!$A$2:$C$72,3,FALSE) -> A | H15: =MIN(VLOOKUP(C15,POs!$B$2:$E$46,4,FALSE)) -> 3 | I15: =(Table1[[#This Row],[Min]]+0.05*Table1[[#This Row],[Min]]) -> 3.15 | K15: 12 | L15: Banda Bracelets (HK) Ltd. | M15: LS1124 | N15: A | O15: =MIN(VLOOKUP(M15,POs!$B$2:$E$46,4,FALSE)) -> 6 | P15: =(Table3[[#This Row],[Min]]+0.05*Table3[[#This Row],[Min]]) -> 6.3
A16: 13 | B16: Banda Bracelets (HK) Ltd. | C16: LS1124 | D16: Leather wrist strap | E16: A | F16: =VLOOKUP(Table1[[#This Row],[Part Number]],'Shelving Inventory list'!$A$2:$C$72,2,FALSE) -> 14 | G16: =VLOOKUP(Table1[[#This Row],[Part Number]],'Shelving Inventory list'!$A$2:$C$72,3,FALSE) -> B | H16: =MIN(VLOOKUP(C16,POs!$B$2:$E$46,4,FALSE)) -> 6 | I16: =(Table1[[#This Row],[Min]]+0.05*Table1[[#This Row],[Min]]) -> 6.3 | K16: 13 | L16: Banda Bracelets (HK) Ltd. | M16: KK433 | N16: A | O16: =MIN(VLOOKUP(M16,POs!$B$2:$E$46,4,FALSE)) -> 3 | P16: =(Table3[[#This Row],[Min]]+0.05*Table3[[#This Row],[Min]]) -> 3.15
A17: 14 | B17: Banda Bracelets (HK) Ltd. | C17: LS1128 | D17: Gold expansion strap | E17: C | F17: =VLOOKUP(Table1[[#This Row],[Part Number]],'Shelving Inventory list'!$A$2:$C$72,2,FALSE) -> 13 | G17: =VLOOKUP(Table1[[#This Row],[Part Number]],'Shelving Inventory list'!$A$2:$C$72,3,FALSE) -> D | H17: =MIN(VLOOKUP(C17,POs!$B$2:$E$46,4,FALSE)) -> 10 | I17: =(Table1[[#This Row],[Min]]+0.05*Table1[[#This Row],[Min]]) -> 10.5 | K17: Total | P17: =SUBTOTAL(109,Table3[Max]) -> 104.11485
A18: 15 | B18: Banda Bracelets (HK) Ltd. | C18: KK425 | D18: Economy TrackR Packaging | E18: B | F18: =VLOOKUP(Table1[[#This Row],[Part Number]],'Shelving Inventory list'!$A$2:$C$72,2,FALSE) -> 14 | G18: =VLOOKUP(Table1[[#This Row],[Part Number]],'Shelving Inventory list'!$A$2:$C$72,3,FALSE) -> A | H18: =MIN(VLOOKUP(C18,POs!$B$2:$E$46,4,FALSE)) -> 2 | I18: =(Table1[[#This Row],[Min]]+0.05*Table1[[#This Row],[Min]]) -> 2.1
A19: 16 | B19: Banda Bracelets (HK) Ltd. | C19: KK433 | D19: Standard TrackR packaging | E19: A | F19: =VLOOKUP(Table1[[#This Row],[Part Number]],'Shelving Inventory list'!$A$2:$C$72,2,FALSE) -> 14 | G19: =VLOOKUP(Table1[[#This Row],[Part Number]],'Shelving Inventory list'!$A$2:$C$72,3,FALSE) -> B | H19: =MIN(VLOOKUP(C19,POs!$B$2:$E$46,4,FALSE)) -> 3 | I19: =(Table1[[#This Row],[Min]]+0.05*Table1[[#This Row],[Min]]) -> 3.15
A20: 17 | B20: Banda Bracelets (HK) Ltd. | C20: KK438 | D20: DeLuxe TrackR packaging | E20: C | F20: =VLOOKUP(Table1[[#This Row],[Part Number]],'Shelving Inventory list'!$A$2:$C$72,2,FALSE) -> 13 | G20: =VLOOKUP(Table1[[#This Row],[Part Number]],'Shelving Inventory list'!$A$2:$C$72,3,FALSE) -> D | H20: =MIN(VLOOKUP(C20,POs!$B$2:$E$46,4,FALSE)) -> 4 | I20: =(Table1[[#This Row],[Min]]+0.05*Table1[[#This Row],[Min]]) -> 4.2
K22: TrackR B | O22: Unit Cost
K23: ID # | L23: Part Number | M23: Description | N23: TrackR Version | O23: Min | P23: Max
A24: Increase max to 5% | K24: 1 | L24: Mitchell’s Plastics | M24: MPC432119-2 | N24: ABC | O24: =MIN(VLOOKUP(M24,POs!$B$1:$E$46,4,FALSE)) -> 6.606 | P24: =(Table4[[#This Row],[Min]]+0.05*Table4[[#This Row],[Min]]) -> 6.9363
K25: 2 | L25: Mitchell’s Plastics | M25: MPC44422 | N25: ABC | O25: =MIN(VLOOKUP(M25,POs!$B$1:$E$46,4,FALSE)) -> 0.081 | P25: =(Table4[[#This Row],[Min]]+0.05*Table4[[#This Row],[Min]]) -> 0.08505
K26: 3 | L26: American Vanadium | M26: SFLV25 | N26: ABC | O26: =MIN(VLOOKUP(M26,POs!$B$1:$E$46,4,FALSE)) -> 17.42 | P26: =(Table4[[#This Row],[Min]]+0.05*Table4[[#This Row],[Min]]) -> 18.291
K27: 4 | L27: Foxconn | M27: FnOFI-GN1212 | N27: ABC | O27: =MIN(VLOOKUP(M27,POs!$B$1:$E$46,4,FALSE)) -> 14.99 | P27: =(Table4[[#This Row],[Min]]+0.05*Table4[[#This Row],[Min]]) -> 15.7395
K28: 5 | L28: Qualcomm | M28: BD2098733AAB | N28: ABC | O28: =MIN(VLOOKUP(M28,POs!$B$1:$E$46,4,FALSE)) -> 4.15 | P28: =(Table4[[#This Row],[Min]]+0.05*Table4[[#This Row],[Min]]) -> 4.3575
K29: 6 | L29: Qualcomm | M29: BD20911131BB | N29: ABC | O29: =MIN(VLOOKUP(M29,POs!$B$1:$E$46,4,FALSE)) -> 1.88 | P29: =(Table4[[#This Row],[Min]]+0.05*Table4[[#This Row],[Min]]) -> 1.974
K30: 7 | L30: ST Microelectronics | M30: HG213123-221 | N30: ABC | O30: =MIN(VLOOKUP(M30,POs!$B$1:$E$46,4,FALSE)) -> 0.57 | P30: =(Table4[[#This Row],[Min]]+0.05*Table4[[#This Row],[Min]]) -> 0.5985
K31: 8 | L31: ST Microelectronics | M31: STMA11233 | N31: ABC | O31: =MIN(VLOOKUP(M31,POs!$B$1:$E$46,4,FALSE)) -> 0.31 | P31: =(Table4[[#This Row],[Min]]+0.05*Table4[[#This Row],[Min]]) -> 0.3255
K32: 9 | L32: Samsung | M32: SS98AAIS | N32: ABC | O32: =MIN(VLOOKUP(M32,POs!$B$1:$E$46,4,FALSE)) -> 38.15 | P32: =(Table4[[#This Row],[Min]]+0.05*Table4[[#This Row],[Min]]) -> 40.0575
K33: 10 | L33: Sandisk | M33: SDMALBB3033G | N33: ABC | O33: =MIN(VLOOKUP(M33,POs!$B$1:$E$46,4,FALSE)) -> 4 | P33: =(Table4[[#This Row],[Min]]+0.05*Table4[[#This Row],[Min]]) -> 4.2
K34: 11 | L34: BlueGiga | M34: BLE112 | N34: ABC | O34: =MIN(VLOOKUP(M34,POs!$B$1:$E$46,4,FALSE)) -> 2 | P34: =(Table4[[#This Row],[Min]]+0.05*Table4[[#This Row],[Min]]) -> 2.1
K35: 12 | L35: Banda Bracelets (HK) Ltd. | M35: LS1121 | N35: B | O35: =MIN(VLOOKUP(M35,POs!$B$1:$E$46,4,FALSE)) -> 3 | P35: =(Table4[[#This Row],[Min]]+0.05*Table4[[#This Row],[Min]]) -> 3.15
K36: 13 | L36: Banda Bracelets (HK) Ltd. | M36: KK425 | N36: B | O36: =MIN(VLOOKUP(M36,POs!$B$1:$E$46,4,FALSE)) -> 2 | P36: =(Table4[[#This Row],[Min]]+0.05*Table4[[#This Row],[Min]]) -> 2.1
K37: Total | P37: =SUBTOTAL(109,Table4[Max]) -> 99.91485
K40: TrackR C | O40: Unit Cost
K41: ID # | L41: Part Number | M41: Description | N41: TrackR Version | O41: Min | P41: Max
K42: 1 | L42: Mitchell’s Plastics | M42: MPC432119-2 | N42: ABC | O42: =MIN(VLOOKUP(M42,POs!$B$2:$E$46,4,FALSE)) -> 6.606 | P42: =(Table5[[#This Row],[Min]]+0.05*Table5[[#This Row],[Min]]) -> 6.9363
K43: 2 | L43: Mitchell’s Plastics | M43: MPC44422 | N43: ABC | O43: =MIN(VLOOKUP(M43,POs!$B$2:$E$46,4,FALSE)) -> 0.081 | P43: =(Table5[[#This Row],[Min]]+0.05*Table5[[#This Row],[Min]]) -> 0.08505
...

Sheet A Picking
A2: Data Sources
B3: The distance data in this table comes from:
A5: Assumptions | C5: Issue | H5: Options # | I5: Description | L5: Chosen | M5: Notes and Sources of Knowledge
B6: 1 | C6: What is the Slow Walking Speed for Picking? | L6: 1.1 | N6: m/sec | O6: Tired persons walking at the end of the shift
H7: 1 | I7: 1.1 | J7: m/sec | L7: take the standard value from google
H8: 2 | I8: 1.15 | J8: m/sec
H9: 3 | I9: 1.2 | J9: m/sec
B11: 2 | C11: What is the Fast Walking Speed for Picking? | L11: 1.8 | N11: m/sec | O11: Persons walking at the start of the shift
H12: 1 | I12: 1.8 | J12: m/sec | L12: take the standard value from google
H13: 2 | I13: 1.9 | J13: m/sec
H14: 3 | I14: 1.95 | J14: m/sec
B16: 3 | C16: What is the time spent picking up a part from a shelf's bay, after a person has walked and is standing in front of it?
H17: 1 | I17: 8 | J17: seconds
H18: 2 | I18: 10 | J18: seconds
A20: Additional Process Knowledge
B21: 1 | C21: The picking Strategy is: | E21: The parts closer to the production area will be picked up first and then the parts which are far from the production area will be picked up
C22: What is the best way to pick? | E22: Picking up multiple parts at the same time while also making sure no part is dropped or damaged in any way which are closer to the production area and then going for parts which are far .
C23: Would this be the same route used for the entire day by everyone? How boring! | H23: Yes
C24: The OHT VP Production VP tells me that each person decides for themselves how to pick components.
C25: - OHT VP Production, May 16
A27: Calculations for Distance, Min and Max Times to pick One Set of Components in preparation for Assembly of those Components
C29: Component | G29: Distance | H29: - time in seconds - | K29: Cumulative Time (seconds)
B30: Pick Seq | C30: ID | D30: Part # | E30: Shelf | F30: Bay | G30: (Meters) | H30: Slow Walk | I30: Fast Walk | J30: Pick from Shelf | K30: Maximum | L30: Minimum
B31: 4 | C31: 1 | D31: MPC432119-2 | E31: =VLOOKUP(Table6[[#This Row],[Part '#]],Table1[[Part Number]:[Shelf]],4,FALSE) -> 10 | F31: =VLOOKUP(Table6[[#This Row],[Part '#]],Table1[[Part Number]:[Bay]],5,FALSE) -> C | G31: 4.7 | H31: 4.273 | I31: 2.611 | J31: 8 | K31: =Table6[[#This Row],[Slow Walk]]+Table6[[#This Row],[Pick from Shelf]] -> 12.273 | L31: =Table6[[#This Row],[Fast Walk]]+Table6[[#This Row],[Pick from Shelf]] -> 10.611
B32: 5 | C32: 2 | D32: MPC44422 | E32: =VLOOKUP(Table6[[#This Row],[Part '#]],Table1[[Part Number]:[Shelf]],4,FALSE) -> 10 | F32: =VLOOKUP(Table6[[#This Row],[Part '#]],Table1[[Part Number]:[Bay]],5,FALSE) -> E | G32: 4.7 | H32: 4.273 | I32: 2.611 | J32: 8 | K32: =K31+Table6[[#This Row],[Slow Walk]]+Table6[[#This Row],[Pick from Shelf]] -> 24.546 | L32: =L31+Table6[[#This Row],[Fast Walk]]+Table6[[#This Row],[Pick from Shelf]] -> 21.222
B33: 12 | C33: 3 | D33: SFLV25 | E33: =VLOOKUP(Table6[[#This Row],[Part '#]],Table1[[Part Number]:[Shelf]],4,FALSE) -> 2 | F33: =VLOOKUP(Table6[[#This Row],[Part '#]],Table1[[Part Number]:[Bay]],5,FALSE) -> A | G33: 3.69 | H33: 3.355 | I33: 2.05 | J33: 8 | K33: =K32+Table6[[#This Row],[Slow Walk]]+Table6[[#This Row],[Pick from Shelf]] -> 35.901 | L33: =L32+Table6[[#This Row],[Fast Walk]]+Table6[[#This Row],[Pick from Shelf]] -> 31.272
B34: 10 | C34: 4 | D34: FnOFI-GN1212 | E34: =VLOOKUP(Table6[[#This Row],[Part '#]],Table1[[Part Number]:[Shelf]],4,FALSE) -> 4 | F34: =VLOOKUP(Table6[[#This Row],[Part '#]],Table1[[Part Number]:[Bay]],5,FALSE) -> D | G34: 2.18 | H34: 1.982 | I34: 1.211 | J34: 8 | K34: =K33+Table6[[#This Row],[Slow Walk]]+Table6[[#This Row],[Pick from Shelf]] -> 45.883 | L34: =L33+Table6[[#This Row],[Fast Walk]]+Table6[[#This Row],[Pick from Shelf]] -> 40.483
B35: 9 | C35: 5 | D35: BD2098733AAB | E35: =VLOOKUP(Table6[[#This Row],[Part '#]],Table1[[Part Number]:[Shelf]],4,FALSE) -> 5 | F35: =VLOOKUP(Table6[[#This Row],[Part '#]],Table1[[Part Number]:[Bay]],5,FALSE) -> E | G35: 3.23 | H35: 2.936 | I35: 1.794 | J35: 8 | K35: =K34+Table6[[#This Row],[Slow Walk]]+Table6[[#This Row],[Pick from Shelf]] -> 56.819 | L35: =L34+Table6[[#This Row],[Fast Walk]]+Table6[[#This Row],[Pick from Shelf]] -> 50.277
B36: 8 | C36: 6 | D36: BD20911131BB | E36: =VLOOKUP(Table6[[#This Row],[Part '#]],Table1[[Part Number]:[Shelf]],4,FALSE) -> 6 | F36: =VLOOKUP(Table6[[#This Row],[Part '#]],Table1[[Part Number]:[Bay]],5,FALSE) -> B | G36: 2.76 | H36: 2.509 | I36: 1.533 | J36: 8 | K36: =K35+Table6[[#This Row],[Slow Walk]]+Table6[[#This Row],[Pick from Shelf]] -> 67.328 | L36: =L35+Table6[[#This Row],[Fast Walk]]+Table6[[#This Row],[Pick from Shelf]] -> 59.81
B37: 6 | C37: 7 | D37: HG213123-221 | E37: =VLOOKUP(Table6[[#This Row],[Part '#]],Table1[[Part Number]:[Shelf]],4,FALSE) -> 7 | F37: =VLOOKUP(Table6[[#This Row],[Part '#]],Table1[[Part Number]:[Bay]],5,FALSE) -> B | G37: 85.11 | H37: 77.373 | I37: 47.283 | J37: 8 | K37: =K36+Table6[[#This Row],[Slow Walk]]+Table6[[#This Row],[Pick from Shelf]] -> 152.701 | L37: =L36+Table6[[#This Row],[Fast Walk]]+Table6[[#This Row],[Pick from Shelf]] -> 115.093
B38: 3 | C38: 8 | D38: STMA11233 | E38: =VLOOKUP(Table6[[#This Row],[Part '#]],Table1[[Part Number]:[Shelf]],4,FALSE) -> 8 | F38: =VLOOKUP(Table6[[#This Row],[Part '#]],Table1[[Part Number]:[Bay]],5,FALSE) -> E | G38: 7.45 | H38: 6.773 | I38: 4.139 | J38: 8 | K38: =K37+Table6[[#This Row],[Slow Walk]]+Table6[[#This Row],[Pick from Shelf]] -> 167.474 | L38: =L37+Table6[[#This Row],[Fast Walk]]+Table6[[#This Row],[Pick from Shelf]] -> 127.232
B39: 7 | C39: 9 | D39: SS98AAIS | E39: =VLOOKUP(Table6[[#This Row],[Part '#]],Table1[[Part Number]:[Shelf]],4,FALSE) -> 7 | F39: =VLOOKUP(Table6[[#This Row],[Part '#]],Table1[[Part Number]:[Bay]],5,FALSE) -> E | G39: 85.11 | H39: 77.373 | I39: 47.283 | J39: 8 | K39: =K38+Table6[[#This Row],[Slow Walk]]+Table6[[#This Row],[Pick from Shelf]] -> 252.847 | L39: =L38+Table6[[#This Row],[Fast Walk]]+Table6[[#This Row],[Pick from Shelf]] -> 182.515
B40: 11 | C40: 10 | D40: SDMALBB3033G | E40: =VLOOKUP(Table6[[#This Row],[Part '#]],Table1[[Part Number]:[Shelf]],4,FALSE) -> 3 | F40: =VLOOKUP(Table6[[#This Row],[Part '#]],Table1[[Part Number]:[Bay]],5,FALSE) -> C | G40: 4.26 | H40: 3.873 | I40: 2.367 | J40: 8 | K40: =K39+Table6[[#This Row],[Slow Walk]]+Table6[[#This Row],[Pick from Shelf]] -> 264.72 | L40: =L39+Table6[[#This Row],[Fast Walk]]+Table6[[#This Row],[Pick from Shelf]] -> 192.882
B41: 13 | C41: 11 | D41: BLE112 | E41: =VLOOKUP(Table6[[#This Row],[Part '#]],Table1[[Part Number]:[Shelf]],4,FALSE) -> 1 | F41: =VLOOKUP(Table6[[#This Row],[Part '#]],Table1[[Part Number]:[Bay]],5,FALSE) -> A | G41: 4.33 | H41: 3.936 | I41: 2.406 | J41: 8 | K41: =K40+Table6[[#This Row],[Slow Walk]]+Table6[[#This Row],[Pick from Shelf]] -> 276.656 | L41: =L40+Table6[[#This Row],[Fast Walk]]+Table6[[#This Row],[Pick from Shelf]] -> 203.288
B42: 1 | C42: 12 | D42: LS1121 | E42: =VLOOKUP(Table6[[#This Row],[Part '#]],Table1[[Part Number]:[Shelf]],4,FALSE) -> 14 | F42: =VLOOKUP(Table6[[#This Row],[Part '#]],Table1[[Part Number]:[Bay]],5,FALSE) -> A | G42: 25.47 | H42: 23.155 | I42: 14.15 | J42: 8 | K42: =K41+Table6[[#This Row],[Slow Walk]]+Table6[[#This Row],[Pick from Shelf]] -> 307.811 | L42: =L41+Table6[[#This Row],[Fast Walk]]+Table6[[#This Row],[Pick from Shelf]] -> 225.438
B43: 2 | C43: 13 | D43: KK433 | E43: =VLOOKUP(Table6[[#This Row],[Part '#]],Table1[[Part Number]:[Shelf]],4,FALSE) -> 14 | F43: =VLOOKUP(Table6[[#This Row],[Part '#]],Table1[[Part Number]:[Bay]],5,FALSE) -> B | G43: 25.47 | H43: 23.155 | I43: 14.15 | J43: 8 | K43: =K42+Table6[[#This Row],[Slow Walk]]+Table6[[#This Row],[Pick from Shelf]] -> 338.966 | L43: =L42+Table6[[#This Row],[Fast Walk]]+Table6[[#This Row],[Pick from Shelf]] -> 247.588
B51: Total Minimum Walking and Picking Time | E51: =MIN(L31:L43) -> 10.611
B52: Total Maximum Walking and Picking Time | E52: =MAX(K31:K43) -> 338.966

Sheet T Picking
A2: Data Sources
B3: The distance data in this table comes from:
A5: Assumptions | C5: Issue | H5: Options # | I5: Description | L5: Chosen | M5: Notes and Sources of Knowledge
B6: 1 | C6: What is the Slow Walking Speed for Picking? | L6: 1.1 | N6: m/sec | O6: Tired persons walking at the end of the shift
H7: 1 | I7: 1.1 | J7: m/sec | L7: take the standard value from google
H8: 2 | I8: 1.15 | J8: m/sec
H9: 3 | I9: 1.2 | J9: m/sec
B11: 2 | C11: What is the Fast Walking Speed for Picking? | L11: 1.8 | N11: m/sec | O11: Persons walking at the start of the shift
H12: 1 | I12: 1.8 | J12: m/sec | L12: take the standard value from google
H13: 2 | I13: 1.9 | J13: m/sec
H14: 3 | I14: 1.95 | J14: m/sec
B16: 3 | C16: What is the time spent picking up a part from a shelf's bay, after a person has walked and is standing in front of it?
H17: 1 | I17: 8 | J17: seconds
H18: 2 | I18: 10 | J18: seconds
A20: Additional Process Knowledge
B21: 1 | C21: The picking Strategy is: | E21: The parts closer to the production area will be picked up first and then the parts which are far from the production area will be picked up
C22: What is the best way to pick? | E22: Picking up multiple parts at the same time while also making sure no part is dropped or damaged in any way which are closer to the production area and then going for parts which are far .
C23: Would this be the same route used for the entire day by everyone? How boring! | H23: Yes
C24: The OHT VP Production VP tells me that each person decides for themselves how to pick components.
C25: - OHT VP Production, May 16
A27: Calculations for Distance, Min and Max Times to pick One Set of Components in preparation for Assembly of those Components
C29: Component | G29: Distance | H29: - time in seconds - | K29: Cumulative Time (seconds)
B30: Pick Seq | C30: ID | D30: Part # | E30: Shelf | F30: Bay | G30: (Meters) | H30: Slow Walk | I30: Fast Walk | J30: Pick from Shelf | K30: Maximum | L30: Minimum
B31: 12 | C31: 1 | D31: MPC432119-2 | E31: =VLOOKUP(Table616[[#This Row],[Part '#]],Table1[[Part Number]:[Shelf]],4,FALSE) -> 10 | F31: =VLOOKUP(Table616[[#This Row],[Part '#]],Table1[[Part Number]:[Bay]],5,FALSE) -> C | G31: 2.6 | H31: =G31/1.1 -> 2.3636364 | I31: =Table616[[#This Row],[(Meters)]]/1.8 -> 1.4444444 | J31: 8 | K31: =Table616[[#This Row],[Slow Walk]]+Table616[[#This Row],[Pick from Shelf]] -> 10.363636 | L31: =Table616[[#This Row],[Fast Walk]]+Table616[[#This Row],[Pick from Shelf]] -> 9.4444444
B32: 13 | C32: 2 | D32: MPC44422 | E32: =VLOOKUP(Table616[[#This Row],[Part '#]],Table1[[Part Number]:[Shelf]],4,FALSE) -> 10 | F32: =VLOOKUP(Table616[[#This Row],[Part '#]],Table1[[Part Number]:[Bay]],5,FALSE) -> E | G32: 2.6 | H32: =G32/1.1 -> 2.3636364 | I32: =Table616[[#This Row],[(Meters)]]/1.8 -> 1.4444444 | J32: 8 | K32: =H32+J32+K31 -> 20.727273 | L32: =I32+J32+L31 -> 18.888889
B33: 2 | C33: 3 | D33: SFLV25 | E33: =VLOOKUP(Table616[[#This Row],[Part '#]],Table1[[Part Number]:[Shelf]],4,FALSE) -> 2 | F33: =VLOOKUP(Table616[[#This Row],[Part '#]],Table1[[Part Number]:[Bay]],5,FALSE) -> A | G33: 2.1 | H33: =G33/1.1 -> 1.9090909 | I33: =Table616[[#This Row],[(Meters)]]/1.8 -> 1.1666667 | J33: 8 | K33: =H33+J33+K32 -> 30.636364 | L33: =I33+J33+L32 -> 28.055556
B34: 7 | C34: 4 | D34: FnOFI-GN1212 | E34: =VLOOKUP(Table616[[#This Row],[Part '#]],Table1[[Part Number]:[Shelf]],4,FALSE) -> 4 | F34: =VLOOKUP(Table616[[#This Row],[Part '#]],Table1[[Part Number]:[Bay]],5,FALSE) -> D | G34: 0.6 | H34: =G34/1.1 -> 0.54545455 | I34: =Table616[[#This Row],[(Meters)]]/1.8 -> 0.33333333 | J34: 8 | K34: =H34+J34+K33 -> 39.181818 | L34: =I34+J34+L33 -> 36.388889
B35: 6 | C35: 5 | D35: BD2098733AAB | E35: =VLOOKUP(Table616[[#This Row],[Part '#]],Table1[[Part Number]:[Shelf]],4,FALSE) -> 5 | F35: =VLOOKUP(Table616[[#This Row],[Part '#]],Table1[[Part Number]:[Bay]],5,FALSE) -> E | G35: 2.3 | H35: =G35/1.1 -> 2.0909091 | I35: =Table616[[#This Row],[(Meters)]]/1.8 -> 1.2777778 | J35: 8 | K35: =H35+J35+K34 -> 49.272727 | L35: =I35+J35+L34 -> 45.666667
B36: 10 | C36: 6 | D36: BD20911131BB | E36: =VLOOKUP(Table616[[#This Row],[Part '#]],Table1[[Part Number]:[Shelf]],4,FALSE) -> 6 | F36: =VLOOKUP(Table616[[#This Row],[Part '#]],Table1[[Part Number]:[Bay]],5,FALSE) -> B | G36: 0.5 | H36: =G36/1.1 -> 0.45454545 | I36: =Table616[[#This Row],[(Meters)]]/1.8 -> 0.27777778 | J36: 8 | K36: =H36+J36+K35 -> 57.727273 | L36: =I36+J36+L35 -> 53.944444
B37: 8 | C37: 7 | D37: HG213123-221 | E37: =VLOOKUP(Table616[[#This Row],[Part '#]],Table1[[Part Number]:[Shelf]],4,FALSE) -> 7 | F37: =VLOOKUP(Table616[[#This Row],[Part '#]],Table1[[Part Number]:[Bay]],5,FALSE) -> B | G37: 8.1 | H37: =G37/1.1 -> 7.3636364 | I37: =Table616[[#This Row],[(Meters)]]/1.8 -> 4.5 | J37: 8 | K37: =H37+J37+K36 -> 73.090909 | L37: =I37+J37+L36 -> 66.444444
B38: 11 | C38: 8 | D38: STMA11233 | E38: =VLOOKUP(Table616[[#This Row],[Part '#]],Table1[[Part Number]:[Shelf]],4,FALSE) -> 8 | F38: =VLOOKUP(Table616[[#This Row],[Part '#]],Table1[[Part Number]:[Bay]],5,FALSE) -> E | G38: 18.2 | H38: =G38/1.1 -> 16.545455 | I38: =Table616[[#This Row],[(Meters)]]/1.8 -> 10.111111 | J38: 8 | K38: =H38+J38+K37 -> 97.636364 | L38: =I38+J38+L37 -> 84.555556
B39: 9 | C39: 9 | D39: SS98AAIS | E39: =VLOOKUP(Table616[[#This Row],[Part '#]],Table1[[Part Number]:[Shelf]],4,FALSE) -> 7 | F39: =VLOOKUP(Table616[[#This Row],[Part '#]],Table1[[Part Number]:[Bay]],5,FALSE) -> E | G39: 4.1 | H39: =G39/1.1 -> 3.7272727 | I39: =Table616[[#This Row],[(Meters)]]/1.8 -> 2.2777778 | J39: 8 | K39: =H39+J39+K38 -> 109.36364 | L39: =I39+J39+L38 -> 94.833333
B40: 3 | C40: 10 | D40: SDMALBB3033G | E40: =VLOOKUP(Table616[[#This Row],[Part '#]],Table1[[Part Number]:[Shelf]],4,FALSE) -> 3 | F40: =VLOOKUP(Table616[[#This Row],[Part '#]],Table1[[Part Number]:[Bay]],5,FALSE) -> C | G40: 1.3 | H40: =G40/1.1 -> 1.1818182 | I40: =Table616[[#This Row],[(Meters)]]/1.8 -> 0.72222222 | J40: 8 | K40: =H40+J40+K39 -> 118.54545 | L40: =I40+J40+L39 -> 103.55556
B41: 1 | C41: 11 | D41: BLE112 | E41: =VLOOKUP(Table616[[#This Row],[Part '#]],Table1[[Part Number]:[Shelf]],4,FALSE) -> 1 | F41: =VLOOKUP(Table616[[#This Row],[Part '#]],Table1[[Part Number]:[Bay]],5,FALSE) -> A | G41: 5.9 | H41: =G41/1.1 -> 5.3636364 | I41: =Table616[[#This Row],[(Meters)]]/1.8 -> 3.2777778 | J41: 8 | K41: =H41+J41+K40 -> 131.90909 | L41: =I41+J41+L40 -> 114.83333
B42: 4 | C42: 12 | D42: LS1121 | E42: =VLOOKUP(Table616[[#This Row],[Part '#]],Table1[[Part Number]:[Shelf]],4,FALSE) -> 14 | F42: =VLOOKUP(Table616[[#This Row],[Part '#]],Table1[[Part Number]:[Bay]],5,FALSE) -> A | G42: 3 | H42: =G42/1.1 -> 2.7272727 | I42: =Table616[[#This Row],[(Meters)]]/1.8 -> 1.6666667 | J42: 8 | K42: =H42+J42+K41 -> 142.63636 | L42: =I42+J42+L41 -> 124.5
B43: 5 | C43: 13 | D43: KK433 | E43: =VLOOKUP(Table616[[#This Row],[Part '#]],Table1[[Part Number]:[Shelf]],4,FALSE) -> 14 | F43: =VLOOKUP(Table616[[#This Row],[Part '#]],Table1[[Part Number]:[Bay]],5,FALSE) -> B | G43: 3 | H43: =G43/1.1 -> 2.7272727 | I43: =Table616[[#This Row],[(Meters)]]/1.8 -> 1.6666667 | J43: 8 | K43: =H43+J43+K42 -> 153.36364 | L43: =I43+J43+L42 -> 134.16667
B51: Total Minimum Walking and Picking Time | E51: =MAX(L31:L43) -> 134.16667
B52: Total Maximum Walking and Picking Time | E52: =MAX(K31:K43) -> 153.36364

Sheet A Assembly
A2: Labour Costing
B3: Type | C3: Worker Type | D3: Cost Per Hour | E3: Per Second
B4: Min | C4: Team Member | D4: =VLOOKUP(C4,Employees!$B$21:$C$33,2,FALSE) -> 22 | E4: 0.0061
B5: Max | C5: Team Lead | D5: =VLOOKUP(C5,Employees!$B$21:$C$33,2,FALSE) -> 26 | E5: 0.0072
A7: Assumptions | C7: Issue | D7: Options # | E7: Description | H7: Chosen | I7: Notes and Sources of Knowledge
B8: 1 | C8: What is the Walking Speed for Assemblers? | H8: Average | J8: m/sec | K8: (This is used in the Responses to Failed tests)
D9: 1 | E9: Slow Walking Speed from Picking | H9: 1.18 | I9: Average of speeds from Picking Sheet | J9: m/sec
D10: 2 | E10: Fast Walking Speed from Picking | H10: 1.75 | I10: Average of speeds from Picking Sheet | J10: m/sec
D11: 3 | E11: Average of the Fast and Slow | H11: 1.47 | J11: m/sec
B13: 2 | C13: Who does the final shipping of the packaged TrackR's? | H13: =E14 -> Maintenance Workers
D14: 1 | E14: Maintenance Workers
D15: 2 | E15: Assembly Workers
D16: 3 | E16: Someone else?
B18: 3 | C18: Who keeps the replacement parts shelf stocked? | H18: =E19 -> Maintenance Workers
D19: 1 | E19: Maintenance Workers
D20: 2 | E20: Assembly Workers
D21: 3 | E21: Someone else?
B23: 4
A27: Additional Process Knowledge
C28: Tug Test Process | D28: The assembly worker grasps the recently soldered part with a special pair of forceps, and pulls with the required amount of force, and no more.
D29: Newly trained assembly workers tend to fail more tug tests, because they pull with too much force. - Comment from Production Lead Hand - May 17th
A31: Common Calculation Factors
B32: 1 | C32: Time to record a failed test for QC | E32: sec | F32: (This is done into either a log book or a computer screen on the Return Goods Shelf)
B33: 2 | C33: Distance from Assembly Table to Return Goods Shelf | H33: meters
B34: 3 | C34: Distance from Return Goods to Replacement Parts | H34: meters
B35: 4 | C35: Distance from Return Goods Shelf to Assembly Table | H35: meters
A37: Assembly Steps - Master List | D37: Picking is not included in this list, and does not need to be included in this list.
B38: Step # | C38: Task | D38: Column1 | E38: Duration(sec) | F38: Total Time | G38: Labour Task Cost (min) | H38: Labour Task Cost (Max) | I38: Labour Cost Total to Task(min) | J38: Labour Cost Total to Task (Max) | K38: Componenent ID# | L38: Component Cost (Min) | M38: Component Cost (Max) | N38: All Total Cost to Task(Min) | O38: All Total Cost to Task (Max) | P38: Failure % | Q38: Action if Test Failed | R38: Additional Time (sec) | S38: More Labour Cost (Min) | T38: More Labour Cost (Max) | U38: Extra Component Cost (Min) | V38: Extra Component Cost (Max) | W38: Total Time to Task with 1 fail and Good Repeat | X38: All Total Cost to Task (Min) | Y38: All Total Cost to Task (max)2 | Z38: Reliability | AA38: Reliability to Task
B39: 1 | C39: Unbox MPC432119-2 | E39: 14 | F39: 14 | G39: =E39*$E$4 -> 0.0854 | H39: =E39*$E$5 -> 0.1008 | I39: =G39 -> 0.0854 | J39: =H39 -> 0.1008 | K39: 1 | L39: =VLOOKUP($K39,Components!$A$3:$I$23,8,FALSE) -> 6.606 | M39: =VLOOKUP($K39,Components!$A$3:$I$23,9,FALSE) -> 6.9363 | N39: =L39+G39 -> 6.6914 | O39: =M39+H39 -> 7.0371 | W39: =F39 -> 14 | X39: =SUM(G39,L39,S39,U39) -> 6.6914 | Y39: =SUM(H39,M39,T39,V39) -> 7.0371 | Z39: 1 | AA39: =Z39 -> 1
B40: 2 | C40: Inspect MPC432119-2 Test A | E40: 5 | F40: =F39+E40 -> 19 | G40: =E40*$E$4 -> 0.0305 | H40: =E40*$E$5 -> 0.036 | I40: =I39+G40 -> 0.1159 | J40: =J39+H40 -> 0.1368 | N40: =N39+L40+G40 -> 6.7219 | O40: =O39+M40+H40 -> 7.0731 | P40: 2 | Q40: Redo Test A | R40: =F83 -> 45.673469 | S40: =$R40*$E$4 -> 0.27860816 | T40: =$R40*$E$5 -> 0.32884898 | U40: =L77 -> 6.606 | V40: =M77 -> 6.9363 | W40: =W39+E40+R40 -> 64.673469 | X40: =SUM(X39,G40,L40,S40,U40) -> 13.606508 | Y40: =SUM(Y39,H40,M40,T40,V40) -> 14.338249 | Z40: =1-P40/100 -> 0.98 | AA40: =Z40*AA39 -> 0.98
B41: 3 | C41: MPC44422 is slid into LS1121 | E41: 3 | F41: =F40+E41 -> 22 | G41: =E41*$E$4 -> 0.0183 | H41: =E41*$E$5 -> 0.0216 | I41: =I40+G41 -> 0.1342 | J41: =J40+H41 -> 0.1584 | K41: 2 | L41: =VLOOKUP($K41,Components!$A$3:$I$23,8,FALSE) -> 0.081 | M41: =VLOOKUP($K41,Components!$A$3:$I$23,9,FALSE) -> 0.08505 | N41: =N40+L41+G41 -> 6.8212 | O41: =O40+M41+H41 -> 7.17975 | W41: =W40+E41+R41 -> 67.673469 | X41: =SUM(X40,G41,L41,S41,U41) -> 13.705808 | Y41: =SUM(Y40,H41,M41,T41,V41) -> 14.444899 | Z41: =1-P41/100 -> 1 | AA41: =Z41*AA40 -> 0.98
B42: 4 | C42: Connect LS112 to MPC432119-2 | E42: 7 | F42: =F41+E42 -> 29 | G42: =E42*$E$4 -> 0.0427 | H42: =E42*$E$5 -> 0.0504 | I42: =I41+G42 -> 0.1769 | J42: =J41+H42 -> 0.2088 | K42: 12 | L42: =VLOOKUP($K42,Components!$A$3:$I$23,8,FALSE) -> 3 | M42: =VLOOKUP($K42,Components!$A$3:$I$23,9,FALSE) -> 3.15 | N42: =N41+L42+G42 -> 9.8639 | O42: =O41+M42+H42 -> 10.38015 | W42: =W41+E42+R42 -> 74.673469 | X42: =SUM(X41,G42,L42,S42,U42) -> 16.748508 | Y42: =SUM(Y41,H42,M42,T42,V42) -> 17.645299 | Z42: =1-P42/100 -> 1 | AA42: =Z42*AA41 -> 0.98
B43: 5 | C43: Tug Test B | E43: 2 | F43: =F42+E43 -> 31 | G43: =E43*$E$4 -> 0.0122 | H43: =E43*$E$5 -> 0.0144 | I43: =I42+G43 -> 0.1891 | J43: =J42+H43 -> 0.2232 | N43: =N42+L43+G43 -> 9.8761 | O43: =O42+M43+H43 -> 10.39455 | P43: 5.2 | Q43: Redo Test B | R43: =F94 -> 36.673469 | S43: =$R43*$E$4 -> 0.22370816 | T43: =$R43*$E$5 -> 0.26404898 | U43: =SUM(L87:L94) -> 3.081 | V43: =SUM(M87:M94) -> 3.23505 | W43: =W42+E43+R43 -> 113.34694 | X43: =SUM(X42,G43,L43,S43,U43) -> 20.065416 | Y43: =SUM(Y42,H43,M43,T43,V43) -> 21.158798 | Z43: =1-P43/100 -> 0.948 | AA43: =Z43*AA42 -> 0.92904
B44: 6 | C44: Place SDMALBB3033G on FnOFI-GN1212 | E44: 6.6 | F44: =F43+E44 -> 37.6 | G44: =E44*$E$4 -> 0.04026 | H44: =E44*$E$5 -> 0.04752 | I44: =I43+G44 -> 0.22936 | J44: =J43+H44 -> 0.27072 | K44: 10 | L44: =VLOOKUP($K44,Components!$A$3:$I$23,8,FALSE) -> 4 | M44: =VLOOKUP($K44,Components!$A$3:$I$23,9,FALSE) -> 4.2 | N44: =N43+L44+G44 -> 13.91636 | O44: =O43+M44+H44 -> 14.64207 | W44: =W43+E44+R44 -> 119.94694 | X44: =SUM(X43,G44,L44,S44,U44) -> 24.105676 | Y44: =SUM(Y43,H44,M44,T44,V44) -> 25.406318 | Z44: =1-P44/100 -> 1 | AA44: =Z44*AA43 -> 0.92904
B45: 7 | C45: Solder FnOFI-GN1212 to SDMALBB3033G | E45: 20 | F45: =F44+E45 -> 57.6 | G45: =E45*$E$4 -> 0.122 | H45: =E45*$E$5 -> 0.144 | I45: =I44+G45 -> 0.35136 | J45: =J44+H45 -> 0.41472 | K45: 4 | L45: =VLOOKUP($K45,Components!$A$3:$I$23,8,FALSE) -> 14.99 | M45: =VLOOKUP($K45,Components!$A$3:$I$23,9,FALSE) -> 15.7395 | N45: =N44+L45+G45 -> 29.02836 | O45: =O44+M45+H45 -> 30.52557 | W45: =W44+E45+R45 -> 139.94694 | X45: =SUM(X44,G45,L45,S45,U45) -> 39.217676 | Y45: =SUM(Y44,H45,M45,T45,V45) -> 41.289818 | Z45: =1-P45/100 -> 1 | AA45: =Z45*AA44 -> 0.92904
B46: 8 | C46: Visual Examination Test C | E46: 30 | F46: =F45+E46 -> 87.6 | G46: =E46*$E$4 -> 0.183 | H46: =E46*$E$5 -> 0.216 | I46: =I45+G46 -> 0.53436 | J46: =J45+H46 -> 0.63072 | N46: =N45+L46+G46 -> 29.21136 | O46: =O45+M46+H46 -> 30.74157 | P46: 2 | Q46: Redo Test C | R46: =F102 -> 37.6 | S46: =$R46*$E$4 -> 0.22936 | T46: =$R46*$E$5 -> 0.27072 | U46: =SUM(L100:L102) -> 18.99 | V46: =SUM(M100:M102) -> 19.9395 | W46: =W45+E46+R46 -> 207.54694 | X46: =SUM(X45,G46,L46,S46,U46) -> 58.620036 | Y46: =SUM(Y45,H46,M46,T46,V46) -> 61.716038 | Z46: =1-P46/100 -> 0.98 | AA46: =Z46*AA45 -> 0.9104592
B47: 9 | C47: Clamp LS112 | E47: 24 | F47: =F46+E47 -> 111.6 | G47: =E47*$E$4 -> 0.1464 | H47: =E47*$E$5 -> 0.1728 | I47: =I46+G47 -> 0.68076 | J47: =J46+H47 -> 0.80352 | N47: =N46+L47+G47 -> 29.35776 | O47: =O46+M47+H47 -> 30.91437 | W47: =W46+E47+R47 -> 231.54694 | X47: =SUM(X46,G47,L47,S47,U47) -> 58.766436 | Y47: =SUM(Y46,H47,M47,T47,V47) -> 61.888838 | Z47: =1-P47/100 -> 1 | AA47: =Z47*AA46 -> 0.9104592
B48: 10 | C48: Solder HG213123-221 to BD2098733AAB | E48: 12 | F48: =F47+E48 -> 123.6 | G48: =E48*$E$4 -> 0.0732 | H48: =E48*$E$5 -> 0.0864 | I48: =I47+G48 -> 0.75396 | J48: =J47+H48 -> 0.88992 | K48: 7 | L48: =VLOOKUP($K48,Components!$A$3:$I$23,8,FALSE) -> 0.57 | M48: =VLOOKUP($K48,Components!$A$3:$I$23,9,FALSE) -> 0.5985 | N48: =N47+L48+G48 -> 30.00096 | O48: =O47+M48+H48 -> 31.59927 | W48: =W47+E48+R48 -> 243.54694 | X48: =SUM(X47,G48,L48,S48,U48) -> 59.409636 | Y48: =SUM(Y47,H48,M48,T48,V48) -> 62.573738 | Z48: =1-P48/100 -> 1 | AA48: =Z48*AA47 -> 0.9104592
B49: 11 | C49: Wait to Ensure bond | E49: 6 | F49: =F48+E49 -> 129.6 | G49: =E49*$E$4 -> 0.0366 | H49: =E49*$E$5 -> 0.0432 | I49: =I48+G49 -> 0.79056 | J49: =J48+H49 -> 0.93312 | N49: =N48+L49+G49 -> 30.03756 | O49: =O48+M49+H49 -> 31.64247 | W49: =W48+E49+R49 -> 249.54694 | X49: =SUM(X48,G49,L49,S49,U49) -> 59.446236 | Y49: =SUM(Y48,H49,M49,T49,V49) -> 62.616938 | Z49: =1-P49/100 -> 1 | AA49: =Z49*AA48 -> 0.9104592
B50: 12 | C50: Tug Test D | E50: 2 | F50: =F49+E50 -> 131.6 | G50: =E50*$E$4 -> 0.0122 | H50: =E50*$E$5 -> 0.0144 | I50: =I49+G50 -> 0.80276 | J50: =J49+H50 -> 0.94752 | N50: =N49+L50+G50 -> 30.04976 | O50: =O49+M50+H50 -> 31.65687 | P50: 7.5 | Q50: Redo Test D | R50: =F115 -> 58.673469 | S50: =$R50*$E$4 -> 0.35790816 | T50: =$R50*$E$5 -> 0.42244898 | U50: =SUM(L107:L115) -> 0.57 | V50: =SUM(M107:M115) -> 0.5985 | W50: =W49+E50+R50 -> 310.22041 | X50: =SUM(X49,G50,L50,S50,U50) -> 60.386344 | Y50: =SUM(Y49,H50,M50,T50,V50) -> 63.652287 | Z50: =1-P50/100 -> 0.925 | AA50: =Z50*AA49 -> 0.84217476
...

Sheet T Assembly
A2: Labour Costing
B3: Type | C3: Worker Type | D3: Cost Per Hour | E3: Per Second
B4: Min | C4: Team Member | D4: =VLOOKUP(C4,Employees!$B$21:$C$33,2,FALSE) -> 22 | E4: 0.0061
B5: Max | C5: Team Lead | D5: =VLOOKUP(C5,Employees!$B$21:$C$33,2,FALSE) -> 26 | E5: 0.0072
A7: Assumptions | C7: Issue | D7: Options # | E7: Description | H7: Chosen | I7: Notes and Sources of Knowledge
B8: 1 | C8: What is the Walking Speed for Assemblers? | H8: Average | J8: m/sec | K8: (This is used in the Responses to Failed tests)
D9: 1 | E9: Slow Walking Speed from Picking | H9: 1.1 | I9: Average of speeds from Picking Sheet | J9: m/sec
D10: 2 | E10: Fast Walking Speed from Picking | H10: 1.8 | I10: Average of speeds from Picking Sheet | J10: m/sec
D11: 3 | E11: Average of the Fast and Slow | H11: 2 | J11: m/sec
B13: 2 | C13: Who does the final shipping of the packaged TrackR's? | H13: =E14 -> Maintenance Workers
D14: 1 | E14: Maintenance Workers
D15: 2 | E15: Assembly Workers
D16: 3 | E16: Someone else?
B18: 3 | C18: Who keeps the replacement parts shelf stocked? | H18: =E19 -> Maintenance Workers
D19: 1 | E19: Maintenance Workers
D20: 2 | E20: Assembly Workers
D21: 3 | E21: Someone else?
B23: 4
A27: Additional Process Knowledge
C28: Tug Test Process | D28: The assembly worker grasps the recently soldered part with a special pair of forceps, and pulls with the required amount of force, and no more.
D29: Newly trained assembly workers tend to fail more tug tests, because they pull with too much force. - Comment from Production Lead Hand - May 17th
A31: Common Calculation Factors
B32: 1 | C32: Time to record a failed test for QC | E32: sec | F32: (This is done into either a log book or a computer screen on the Return Goods Shelf)
B33: 2 | C33: Distance from Assembly Table to Return Goods Shelf | G33: 7.9 | H33: meters
B34: 3 | C34: Distance from Return Goods to Replacement Parts | G34: 9.6 | H34: meters
B35: 4 | C35: Distance from Return Goods Shelf to Assembly Table | G35: 7.9 | H35: meters
A37: Assembly Steps - Master List | D37: Picking is not included in this list, and does not need to be included in this list.
B38: Step # | C38: Task | D38: Column1 | E38: Duration(sec) | F38: Total Time | G38: Labour Task Cost (min) | H38: Labour Task Cost (Max) | I38: Labour Cost Total to Task(min) | J38: Labour Cost Total to Task (Max) | K38: Componenent ID# | L38: Component Cost (Min) | M38: Component Cost (Max) | N38: All Total Cost to Task(Min) | O38: All Total Cost to Task (Max) | P38: Failure % | Q38: Action if Test Failed | R38: Additional Time (sec) | S38: More Labour Cost (Min) | T38: More Labour Cost (Max) | U38: Extra Component Cost (Min) | V38: Extra Component Cost (Max) | W38: Total Time to Task with 1 fail and Good Repeat | X38: All Total Cost to Task (Min) | Y38: All Total Cost to Task (max)2 | Z38: Reliability | AA38: Reliability to Task
B39: 1 | C39: Unbox MPC432119-2 | D39: 1 | E39: 14 | F39: 14 | G39: =E39*$E$4 -> 0.0854 | H39: =E39*$E$5 -> 0.1008 | I39: =G39 -> 0.0854 | J39: =H39 -> 0.1008 | K39: 1 | L39: =VLOOKUP($K39,Components!$A$3:$I$23,8,FALSE) -> 6.606 | M39: =VLOOKUP($K39,Components!$A$3:$I$23,9,FALSE) -> 6.9363 | N39: =L39+G39 -> 6.6914 | O39: =M39+H39 -> 7.0371 | W39: =F39 -> 14 | X39: =SUM(G39,L39,S39,U39) -> 6.6914 | Y39: =SUM(H39,M39,T39,V39) -> 7.0371 | Z39: 1 | AA39: =Z39 -> 1
B40: 2 | C40: Inspect MPC432119-2 Test A | D40: 1 | E40: 5 | F40: =F39+E40 -> 19 | G40: =E40*$E$4 -> 0.0305 | H40: =E40*$E$5 -> 0.036 | I40: =I39+G40 -> 0.1159 | J40: =J39+H40 -> 0.1368 | N40: =N39+L40+G40 -> 6.7219 | O40: =O39+M40+H40 -> 7.0731 | P40: 2 | Q40: Redo Test A | R40: =F83 -> 44.7 | S40: =$R40*$E$4 -> 0.27267 | T40: =$R40*$E$5 -> 0.32184 | U40: =L77 -> 6.606 | V40: =M77 -> 6.9363 | W40: =W39+E40+R40 -> 63.7 | X40: =SUM(X39,G40,L40,S40,U40) -> 13.60057 | Y40: =SUM(Y39,H40,M40,T40,V40) -> 14.33124 | Z40: =1-P40/100 -> 0.98 | AA40: =Z40*AA39 -> 0.98
B41: 3 | C41: MPC44422 is slid into LS1121 | D41: 2 | E41: 3 | F41: =F40+E41 -> 22 | G41: =E41*$E$4 -> 0.0183 | H41: =E41*$E$5 -> 0.0216 | I41: =I40+G41 -> 0.1342 | J41: =J40+H41 -> 0.1584 | K41: 2 | L41: =VLOOKUP($K41,Components!$A$3:$I$23,8,FALSE) -> 0.081 | M41: =VLOOKUP($K41,Components!$A$3:$I$23,9,FALSE) -> 0.08505 | N41: =N40+L41+G41 -> 6.8212 | O41: =O40+M41+H41 -> 7.17975 | W41: =W40+E41+R41 -> 66.7 | X41: =SUM(X40,G41,L41,S41,U41) -> 13.69987 | Y41: =SUM(Y40,H41,M41,T41,V41) -> 14.43789 | Z41: =1-P41/100 -> 1 | AA41: =Z41*AA40 -> 0.98
B42: 4 | C42: Connect LS112 to MPC432119-2 | D42: 2 | E42: 7 | F42: =F41+E42 -> 29 | G42: =E42*$E$4 -> 0.0427 | H42: =E42*$E$5 -> 0.0504 | I42: =I41+G42 -> 0.1769 | J42: =J41+H42 -> 0.2088 | K42: 12 | L42: =VLOOKUP($K42,Components!$A$3:$I$23,8,FALSE) -> 3 | M42: =VLOOKUP($K42,Components!$A$3:$I$23,9,FALSE) -> 3.15 | N42: =N41+L42+G42 -> 9.8639 | O42: =O41+M42+H42 -> 10.38015 | W42: =W41+E42+R42 -> 73.7 | X42: =SUM(X41,G42,L42,S42,U42) -> 16.74257 | Y42: =SUM(Y41,H42,M42,T42,V42) -> 17.63829 | Z42: =1-P42/100 -> 1 | AA42: =Z42*AA41 -> 0.98
B43: 5 | C43: Tug Test B | D43: 3 | E43: 2 | F43: =F42+E43 -> 31 | G43: =E43*$E$4 -> 0.0122 | H43: =E43*$E$5 -> 0.0144 | I43: =I42+G43 -> 0.1891 | J43: =J42+H43 -> 0.2232 | N43: =N42+L43+G43 -> 9.8761 | O43: =O42+M43+H43 -> 10.39455 | P43: 5.2 | Q43: Redo Test B | R43: =F94 -> 35.7 | S43: =$R43*$E$4 -> 0.21777 | T43: =$R43*$E$5 -> 0.25704 | U43: =SUM(L87:L94) -> 3.081 | V43: =SUM(M87:M94) -> 3.23505 | W43: =W42+E43+R43 -> 111.4 | X43: =SUM(X42,G43,L43,S43,U43) -> 20.05354 | Y43: =SUM(Y42,H43,M43,T43,V43) -> 21.14478 | Z43: =1-P43/100 -> 0.948 | AA43: =Z43*AA42 -> 0.92904
B44: 6 | C44: Place SDMALBB3033G on FnOFI-GN1212 | D44: 1 | E44: 6.6 | F44: =F43+E44 -> 37.6 | G44: =E44*$E$4 -> 0.04026 | H44: =E44*$E$5 -> 0.04752 | I44: =I43+G44 -> 0.22936 | J44: =J43+H44 -> 0.27072 | K44: 10 | L44: =VLOOKUP($K44,Components!$A$3:$I$23,8,FALSE) -> 4 | M44: =VLOOKUP($K44,Components!$A$3:$I$23,9,FALSE) -> 4.2 | N44: =N43+L44+G44 -> 13.91636 | O44: =O43+M44+H44 -> 14.64207 | W44: =W43+E44+R44 -> 118 | X44: =SUM(X43,G44,L44,S44,U44) -> 24.0938 | Y44: =SUM(Y43,H44,M44,T44,V44) -> 25.3923 | Z44: =1-P44/100 -> 1 | AA44: =Z44*AA43 -> 0.92904
B45: 7 | C45: Solder FnOFI-GN1212 to SDMALBB3033G | D45: 2 | E45: 20 | F45: =F44+E45 -> 57.6 | G45: =E45*$E$4 -> 0.122 | H45: =E45*$E$5 -> 0.144 | I45: =I44+G45 -> 0.35136 | J45: =J44+H45 -> 0.41472 | K45: 4 | L45: =VLOOKUP($K45,Components!$A$3:$I$23,8,FALSE) -> 14.99 | M45: =VLOOKUP($K45,Components!$A$3:$I$23,9,FALSE) -> 15.7395 | N45: =N44+L45+G45 -> 29.02836 | O45: =O44+M45+H45 -> 30.52557 | W45: =W44+E45+R45 -> 138 | X45: =SUM(X44,G45,L45,S45,U45) -> 39.2058 | Y45: =SUM(Y44,H45,M45,T45,V45) -> 41.2758 | Z45: =1-P45/100 -> 1 | AA45: =Z45*AA44 -> 0.92904
B46: 8 | C46: Visual Examination Test C | D46: 3 | E46: 30 | F46: =F45+E46 -> 87.6 | G46: =E46*$E$4 -> 0.183 | H46: =E46*$E$5 -> 0.216 | I46: =I45+G46 -> 0.53436 | J46: =J45+H46 -> 0.63072 | N46: =N45+L46+G46 -> 29.21136 | O46: =O45+M46+H46 -> 30.74157 | P46: 2 | Q46: Redo Test C | R46: =F102 -> 37.6 | S46: =$R46*$E$4 -> 0.22936 | T46: =$R46*$E$5 -> 0.27072 | U46: =SUM(L100:L102) -> 18.99 | V46: =SUM(M100:M102) -> 19.9395 | W46: =W45+E46+R46 -> 205.6 | X46: =SUM(X45,G46,L46,S46,U46) -> 58.60816 | Y46: =SUM(Y45,H46,M46,T46,V46) -> 61.70202 | Z46: =1-P46/100 -> 0.98 | AA46: =Z46*AA45 -> 0.9104592
B47: 9 | C47: Clamp LS112 | D47: 4 | E47: 24 | F47: =F46+E47 -> 111.6 | G47: =E47*$E$4 -> 0.1464 | H47: =E47*$E$5 -> 0.1728 | I47: =I46+G47 -> 0.68076 | J47: =J46+H47 -> 0.80352 | N47: =N46+L47+G47 -> 29.35776 | O47: =O46+M47+H47 -> 30.91437 | W47: =W46+E47+R47 -> 229.6 | X47: =SUM(X46,G47,L47,S47,U47) -> 58.75456 | Y47: =SUM(Y46,H47,M47,T47,V47) -> 61.87482 | Z47: =1-P47/100 -> 1 | AA47: =Z47*AA46 -> 0.9104592
B48: 10 | C48: Solder HG213123-221 to BD2098733AAB | D48: 4 | E48: 12 | F48: =F47+E48 -> 123.6 | G48: =E48*$E$4 -> 0.0732 | H48: =E48*$E$5 -> 0.0864 | I48: =I47+G48 -> 0.75396 | J48: =J47+H48 -> 0.88992 | K48: 7 | L48: =VLOOKUP($K48,Components!$A$3:$I$23,8,FALSE) -> 0.57 | M48: =VLOOKUP($K48,Components!$A$3:$I$23,9,FALSE) -> 0.5985 | N48: =N47+L48+G48 -> 30.00096 | O48: =O47+M48+H48 -> 31.59927 | W48: =W47+E48+R48 -> 241.6 | X48: =SUM(X47,G48,L48,S48,U48) -> 59.39776 | Y48: =SUM(Y47,H48,M48,T48,V48) -> 62.55972 | Z48: =1-P48/100 -> 1 | AA48: =Z48*AA47 -> 0.9104592
B49: 11 | C49: Wait to Ensure bond | D49: 4 | E49: 6 | F49: =F48+E49 -> 129.6 | G49: =E49*$E$4 -> 0.0366 | H49: =E49*$E$5 -> 0.0432 | I49: =I48+G49 -> 0.79056 | J49: =J48+H49 -> 0.93312 | N49: =N48+L49+G49 -> 30.03756 | O49: =O48+M49+H49 -> 31.64247 | W49: =W48+E49+R49 -> 247.6 | X49: =SUM(X48,G49,L49,S49,U49) -> 59.43436 | Y49: =SUM(Y48,H49,M49,T49,V49) -> 62.60292 | Z49: =1-P49/100 -> 1 | AA49: =Z49*AA48 -> 0.9104592
B50: 12 | C50: Tug Test D | D50: 3 | E50: 2 | F50: =F49+E50 -> 131.6 | G50: =E50*$E$4 -> 0.0122 | H50: =E50*$E$5 -> 0.0144 | I50: =I49+G50 -> 0.80276 | J50: =J49+H50 -> 0.94752 | N50: =N49+L50+G50 -> 30.04976 | O50: =O49+M50+H50 -> 31.65687 | P50: 7.5 | Q50: Redo Test D | R50: =F115 -> 57.7 | S50: =$R50*$E$4 -> 0.35197 | T50: =$R50*$E$5 -> 0.41544 | U50: =SUM(L107:L115) -> 0.57 | V50: =SUM(M107:M115) -> 0.5985 | W50: =W49+E50+R50 -> 307.3 | X50: =SUM(X49,G50,L50,S50,U50) -> 60.36853 | Y50: =SUM(Y49,H50,M50,T50,V50) -> 63.63126 | Z50: =1-P50/100 -> 0.925 | AA50: =Z50*AA49 -> 0.84217476
...

Sheet A P&L
A1: As-Is Profit And loss
A3: Assumptions | C3: Issue | D3: Options # | E3: Description | H3: Chosen | I3: Notes and Sources of Knowledge
B4: 1 | C4: Is the Final Testing time included in the Assembly time (Calc Factor 1) for this model? | H4: No | I4: Directed by the Senior BA
C5: *** Final Testing is Done at the 4th Assembly Table *** | D5: 1 | E5: Yes
D6: 2 | E6: No
B8: 2 | C8: Should the production limit per day be built into this Calculation Model? | H8: No | I8: Directed by the Senior BA
C9: ** See point 1 in Additional Process Knowledge *** | D9: 1 | E9: Yes
D10: 2 | E10: No
B12: 3 | C12: Are shipping costs included in this model? | H12: No | I12: Shipping is Paid back by the TrackR Buyer
D13: 1 | E13: Yes
D14: 2 | E14: No
A16: Additional Process Knowledge
B17: 1 | C17: Current policy - Daily Limit of TrackR Production
C18: OHT will not build more TrackR's that it can sell in one day. In fact, it doesn't build a TRackR until it has an order for that TrackR.
C19: So, when enough TrackR's are built to meet orders, then production stops.
C20: Source - OHT Production VP - May 16
B22: 2 | C22: Current Policy - Picking of Components, and then Assembly
C23: Each Assembly worker - Lead Hand or not - walks and picks the needed components for one TrackR,
C24: and then, when an Assembly Table is available, steps to the assembly table
C25: and proceeds to perform all necessary actions and tests to asemble a Good TrackR.
C26: Source - OHT Production VP - May 16
B28: 3 | C28: All 3 Assembly Tables must be used continually until the daily limit is met
C29: So, often persons are standing still, with their picked components, waiting for an assembly table.
C30: Source - OHT Production VP - May 16
A33: Common Calculation Factors
B34: 1 | C34: Average Time for one worker to assemble and test one TrackR | D34: =(('A Assembly'!W69+'A Assembly'!F69)/2)/60 -> 7.3013946 | E34: Minutes
B35: 2 | C35: Average Time for one worker to pick one set of TrackR components, for one version | D35: =(('A Picking'!K43+'A Picking'!L43)/2)/60 -> 4.88795 | E35: Minutes
B36: 3 | C36: Hours of shift per day | D36: 7.5 | E36: Hours
B37: 4 | C37: Number of Assembly Tables in Use | D37: 3 | E37: Tables
B38: 5 | C38: Number of Shifts Per Day | D38: 2 | E38: Shifts
B39: 6 | C39: Failure Rate of Final Test | D39: ='A Assembly'!P67/100 -> 0.02
B40: 7 | C40: Failure Rate of Heat Test | D40: ='A Assembly'!P64/100 -> 0.095
B41: 8 | C41: Marketing Cost per TrackR (income for the Marketing Group) | D41: 10
A43: TrackR Production - Profit and Loss Estimate Model
B45: Gross Income Per Average Day
C46: Productive Work Time per hour (1 - Maintenance Time) | D46: 1 | E46: Hours
C47: Hours shift per day | D47: =D36 -> 7.5 | E47: Hours
C49: TrackRs made per hour Per Table | D49: =D46/(D34/60) -> 8.2176082 | E49: TrackRs per Hour
C50: TrackRs made per Table Per Shift | D50: =D49*D47 -> 61.632062 | E50: TrackRs per Shift
C51: ="TrackRs made by "&D37&" tables Per Shift" -> TrackRs made by 3 tables Per Shift | D51: =D50*D37 -> 184.89619 | E51: TrackR
...

Sheet T P&L
A1: As-Is Profit And loss
A3: Assumptions | C3: Issue | D3: Options # | E3: Description | H3: Chosen | I3: Notes and Sources of Knowledge
B4: 1 | C4: Is the Final Testing time included in the Assembly time (Calc Factor 1) for this model? | H4: No | I4: Directed by the Senior BA
C5: *** Final Testing is Done at the 4th Assembly Table *** | D5: 1 | E5: Yes
D6: 2 | E6: No
B8: 2 | C8: Should the production limit per day be built into this Calculation Model? | H8: No | I8: Directed by the Senior BA
C9: ** See point 1 in Additional Process Knowledge *** | D9: 1 | E9: Yes
D10: 2 | E10: No
B12: 3 | C12: Are shipping costs included in this model? | H12: No | I12: Shipping is Paid back by the TrackR Buyer
D13: 1 | E13: Yes
D14: 2 | E14: No
A16: Additional Process Knowledge
B17: 1 | C17: Current policy - Daily Limit of TrackR Production
C18: OHT will not build more TrackR's that it can sell in one day. In fact, it doesn't build a TRackR until it has an order for that TrackR.
C19: So, when enough TrackR's are built to meet orders, then production stops.
C20: Source - OHT Production VP - May 16
B22: 2 | C22: Current Policy - Picking of Components, and then Assembly
C23: Each Assembly worker - Lead Hand or not - walks and picks the needed components for one TrackR,
C24: and then, when an Assembly Table is available, steps to the assembly table
C25: and proceeds to perform all necessary actions and tests to asemble a Good TrackR.
C26: Source - OHT Production VP - May 16
B28: 3 | C28: All 3 Assembly Tables must be used continually until the daily limit is met
C29: So, often persons are standing still, with their picked components, waiting for an assembly table.
C30: Source - OHT Production VP - May 16
A33: Common Calculation Factors
B34: 1 | C34: Average Time for one worker to assemble and test one TrackR | D34: =(('T Assembly'!W69+'T Assembly'!F69)/2)/60 -> 6.7941667 | E34: Minutes
B35: 2 | C35: Average Time for one worker to pick one set of TrackR components, for one version | D35: =(('T Picking'!K43+'T Picking'!L43)/2)/60 -> 2.3960859 | E35: Minutes
B36: 3 | C36: Hours of shift per day | D36: 4 | E36: Hours
B37: 4 | C37: Number of Assembly Tables in Use | D37: 3 | E37: Tables
B38: 5 | C38: Number of Shifts Per Day | D38: 2 | E38: Shifts
B39: 6 | C39: Failure Rate of Final Test | D39: ='A Assembly'!P67/100 -> 0.02
B40: 7 | C40: Failure Rate of Heat Test | D40: ='A Assembly'!P64/100 -> 0.095
B41: 8 | C41: Marketing Cost per TrackR (income for the Marketing Group) | D41: 10
A43: TrackR Production - Profit and Loss Estimate Model
B45: Gross Income Per Average Day
C46: Productive Work Time per hour (1 - Maintenance Time) | D46: 1 | E46: Hours
C47: Hours shift per day | D47: =D36 -> 4 | E47: Hours
C49: TrackRs made per hour Per Table | D49: =D46/(D34/60) -> 8.8311051 | E49: TrackRs per Hour
C50: TrackRs made per Table Per Shift | D50: =D49*D47 -> 35.32442 | E50: TrackRs per Shift
C51: ="TrackRs made by "&D37&" tables Per Shift" -> TrackRs made by 3 tables Per Shift | D51: =D50*D37 -> 105.97326 | E51: TrackR
...

Sheet Sunny Day
A1: As-Is Profit And loss
A3: Assumptions | C3: Issue | D3: Options # | E3: Description | H3: Chosen | I3: Notes and Sources of Knowledge
B4: 1 | C4: Is the Final Testing time included in the Assembly time (Calc Factor 1) for this model? | H4: No | I4: Directed by the Senior BA
C5: *** Final Testing is Done at the 4th Assembly Table *** | D5: 1 | E5: Yes
D6: 2 | E6: No
B8: 2 | C8: Should the production limit per day be built into this Calculation Model? | H8: No | I8: Directed by the Senior BA
C9: ** See point 1 in Additional Process Knowledge *** | D9: 1 | E9: Yes
D10: 2 | E10: No
B12: 3 | C12: Are shipping costs included in this model? | H12: No | I12: Shipping is Paid back by the TrackR Buyer
D13: 1 | E13: Yes
D14: 2 | E14: No
A16: Additional Process Knowledge
B17: 1 | C17: Current policy - Daily Limit of TrackR Production
C18: OHT will not build more TrackR's that it can sell in one day. In fact, it doesn't build a TRackR until it has an order for that TrackR.
C19: So, when enough TrackR's are built to meet orders, then production stops.
C20: Source - OHT Production VP - May 16
B22: 2 | C22: Current Policy - Picking of Components, and then Assembly
C23: Each Assembly worker - Lead Hand or not - walks and picks the needed components for one TrackR,
C24: and then, when an Assembly Table is available, steps to the assembly table
C25: and proceeds to perform all necessary actions and tests to asemble a Good TrackR.
C26: Source - OHT Production VP - May 16
B28: 3 | C28: All 3 Assembly Tables must be used continually until the daily limit is met
C29: So, often persons are standing still, with their picked components, waiting for an assembly table.
C30: Source - OHT Production VP - May 16
A33: Common Calculation Factors
B34: 1 | C34: Fast Time for one worker to assemble and test one TrackR | D34: ='T Assembly'!F69/60 -> 4.4583333 | E34: Minutes
B35: 2 | C35: Average Time for one worker to pick one set of TrackR components, for one version | D35: ='T Picking'!K43/60 -> 2.5560606 | E35: Minutes
B36: 3 | C36: Hours of shift per day | D36: 4 | E36: Hours
B37: 4 | C37: Number of Assembly Tables in Use | D37: 3 | E37: Tables
B38: 5 | C38: Number of Shifts Per Day | D38: 2 | E38: Shifts
B39: 6 | C39: Failure Rate of Final Test | D39: 0
B40: 7 | C40: Failure Rate of Heat Test | D40: 0
B41: 8 | C41: Marketing Cost per TrackR (income for the Marketing Group) | D41: 10
A43: TrackR Production - Profit and Loss Estimate Model
B45: Gross Income Per Average Day
C46: Productive Work Time per hour (1 - Maintenance Time) | D46: 1 | E46: Hours
C47: Hours shift per day | D47: =D36 -> 4 | E47: Hours
C49: TrackRs made per hour Per Table | D49: =D46/(D34/60) -> 13.457944 | E49: TrackRs per Hour
C50: TrackRs made per Table Per Shift | D50: =D49*D47 -> 53.831776 | E50: TrackRs per Shift
C51: ="TrackRs made by "&D37&" tables Per Shift" -> TrackRs made by 3 tables Per Shift | D51: =D50*D37 -> 161.49533 | E51: TrackR
...

Sheet Rainy Day
A1: As-Is Profit And loss
A3: Assumptions | C3: Issue | D3: Options # | E3: Description | H3: Chosen | I3: Notes and Sources of Knowledge
B4: 1 | C4: Is the Final Testing time included in the Assembly time (Calc Factor 1) for this model? | H4: No | I4: Directed by the Senior BA
C5: *** Final Testing is Done at the 4th Assembly Table *** | D5: 1 | E5: Yes
D6: 2 | E6: No
B8: 2 | C8: Should the production limit per day be built into this Calculation Model? | H8: No | I8: Directed by the Senior BA
C9: ** See point 1 in Additional Process Knowledge *** | D9: 1 | E9: Yes
D10: 2 | E10: No
B12: 3 | C12: Are shipping costs included in this model? | H12: No | I12: Shipping is Paid back by the TrackR Buyer
D13: 1 | E13: Yes
D14: 2 | E14: No
A16: Additional Process Knowledge
B17: 1 | C17: Current policy - Daily Limit of TrackR Production
C18: OHT will not build more TrackR's that it can sell in one day. In fact, it doesn't build a TRackR until it has an order for that TrackR.
